{
 "cells": [
  {
   "cell_type": "code",
   "execution_count": 1,
   "id": "be00ef90",
   "metadata": {},
   "outputs": [
    {
     "name": "stdout",
     "output_type": "stream",
     "text": [
      "WARNING:tensorflow:From E:\\Apps\\Anaconda\\Lib\\site-packages\\keras\\src\\losses.py:2976: The name tf.losses.sparse_softmax_cross_entropy is deprecated. Please use tf.compat.v1.losses.sparse_softmax_cross_entropy instead.\n",
      "\n"
     ]
    }
   ],
   "source": [
    "import pandas as pd\n",
    "from sklearn.model_selection import train_test_split\n",
    "from sklearn.feature_extraction.text import TfidfVectorizer\n",
    "from tensorflow.keras.models import Sequential\n",
    "from tensorflow.keras.layers import Dense, Embedding, LSTM, GlobalMaxPooling1D\n",
    "from tensorflow.keras.optimizers import Adam\n",
    "from sklearn.preprocessing import LabelEncoder"
   ]
  },
  {
   "cell_type": "code",
   "execution_count": 2,
   "id": "6a1e2349",
   "metadata": {},
   "outputs": [],
   "source": [
    "# Load the dataset\n",
    "df = pd.read_csv('./food_recipes.csv')\n",
    "\n",
    "X = df['ingredients']\n",
    "y = df['recipe_title']\n",
    "\n",
    "# Split the data into training and testing sets\n",
    "X_train, X_test, y_train, y_test = train_test_split(X, y, test_size=0.2, random_state=42)\n",
    "\n",
    "#Fill nulls with empty strings\n",
    "X_train = X_train.fillna('')\n",
    "X_test = X_test.fillna('')\n",
    "y_train = y_train.fillna('')  \n",
    "y_test = y_test.fillna('')"
   ]
  },
  {
   "cell_type": "code",
   "execution_count": 3,
   "id": "5c58ae8c",
   "metadata": {},
   "outputs": [],
   "source": [
    "# Text vectorization using TF-IDF\n",
    "vectorizer = TfidfVectorizer(max_features=5000)\n",
    "X_train_vec = vectorizer.fit_transform(X_train)\n",
    "X_test_vec = vectorizer.transform(X_test)"
   ]
  },
  {
   "cell_type": "code",
   "execution_count": 4,
   "id": "585c9d02",
   "metadata": {},
   "outputs": [
    {
     "name": "stdout",
     "output_type": "stream",
     "text": [
      "WARNING:tensorflow:From E:\\Apps\\Anaconda\\Lib\\site-packages\\keras\\src\\backend.py:873: The name tf.get_default_graph is deprecated. Please use tf.compat.v1.get_default_graph instead.\n",
      "\n"
     ]
    }
   ],
   "source": [
    "# Define the model\n",
    "model = Sequential()\n",
    "model.add(Embedding(input_dim=5000, output_dim=64, input_length=X_train_vec.shape[1]))\n",
    "# model.add(LSTM(100, return_sequences=True))\n",
    "# model.add(GlobalMaxPooling1D())\n",
    "model.add(Dense(50, activation='relu'))\n",
    "model.add(Dense(len(df['recipe_title'].unique()), activation='softmax'))"
   ]
  },
  {
   "cell_type": "code",
   "execution_count": 5,
   "id": "7cb91842",
   "metadata": {},
   "outputs": [],
   "source": [
    "# Compile the model\n",
    "model.compile(optimizer=Adam(learning_rate=0.001), loss='sparse_categorical_crossentropy', metrics=['accuracy'])"
   ]
  },
  {
   "cell_type": "code",
   "execution_count": 18,
   "id": "3ddf716e",
   "metadata": {},
   "outputs": [],
   "source": []
  },
  {
   "cell_type": "code",
   "execution_count": 6,
   "id": "d5a3e0a5",
   "metadata": {},
   "outputs": [],
   "source": [
    "# Convert labels to numerical format\n",
    "label_encoder = LabelEncoder()\n",
    "y_train_encoded = label_encoder.fit_transform(y_train)"
   ]
  },
  {
   "cell_type": "code",
   "execution_count": 7,
   "id": "257094fa",
   "metadata": {},
   "outputs": [
    {
     "name": "stdout",
     "output_type": "stream",
     "text": [
      "Epoch 1/5\n",
      "WARNING:tensorflow:From E:\\Apps\\Anaconda\\Lib\\site-packages\\keras\\src\\utils\\tf_utils.py:492: The name tf.ragged.RaggedTensorValue is deprecated. Please use tf.compat.v1.ragged.RaggedTensorValue instead.\n",
      "\n",
      "WARNING:tensorflow:From E:\\Apps\\Anaconda\\Lib\\site-packages\\keras\\src\\engine\\base_layer_utils.py:384: The name tf.executing_eagerly_outside_functions is deprecated. Please use tf.compat.v1.executing_eagerly_outside_functions instead.\n",
      "\n"
     ]
    },
    {
     "ename": "InvalidArgumentError",
     "evalue": "Graph execution error:\n\nDetected at node sparse_categorical_crossentropy/SparseSoftmaxCrossEntropyWithLogits/SparseSoftmaxCrossEntropyWithLogits defined at (most recent call last):\n  File \"<frozen runpy>\", line 198, in _run_module_as_main\n\n  File \"<frozen runpy>\", line 88, in _run_code\n\n  File \"E:\\Apps\\Anaconda\\Lib\\site-packages\\ipykernel_launcher.py\", line 17, in <module>\n\n  File \"E:\\Apps\\Anaconda\\Lib\\site-packages\\traitlets\\config\\application.py\", line 992, in launch_instance\n\n  File \"E:\\Apps\\Anaconda\\Lib\\site-packages\\ipykernel\\kernelapp.py\", line 736, in start\n\n  File \"E:\\Apps\\Anaconda\\Lib\\site-packages\\tornado\\platform\\asyncio.py\", line 195, in start\n\n  File \"E:\\Apps\\Anaconda\\Lib\\asyncio\\base_events.py\", line 607, in run_forever\n\n  File \"E:\\Apps\\Anaconda\\Lib\\asyncio\\base_events.py\", line 1922, in _run_once\n\n  File \"E:\\Apps\\Anaconda\\Lib\\asyncio\\events.py\", line 80, in _run\n\n  File \"E:\\Apps\\Anaconda\\Lib\\site-packages\\ipykernel\\kernelbase.py\", line 516, in dispatch_queue\n\n  File \"E:\\Apps\\Anaconda\\Lib\\site-packages\\ipykernel\\kernelbase.py\", line 505, in process_one\n\n  File \"E:\\Apps\\Anaconda\\Lib\\site-packages\\ipykernel\\kernelbase.py\", line 412, in dispatch_shell\n\n  File \"E:\\Apps\\Anaconda\\Lib\\site-packages\\ipykernel\\kernelbase.py\", line 740, in execute_request\n\n  File \"E:\\Apps\\Anaconda\\Lib\\site-packages\\ipykernel\\ipkernel.py\", line 422, in do_execute\n\n  File \"E:\\Apps\\Anaconda\\Lib\\site-packages\\ipykernel\\zmqshell.py\", line 546, in run_cell\n\n  File \"E:\\Apps\\Anaconda\\Lib\\site-packages\\IPython\\core\\interactiveshell.py\", line 3024, in run_cell\n\n  File \"E:\\Apps\\Anaconda\\Lib\\site-packages\\IPython\\core\\interactiveshell.py\", line 3079, in _run_cell\n\n  File \"E:\\Apps\\Anaconda\\Lib\\site-packages\\IPython\\core\\async_helpers.py\", line 129, in _pseudo_sync_runner\n\n  File \"E:\\Apps\\Anaconda\\Lib\\site-packages\\IPython\\core\\interactiveshell.py\", line 3284, in run_cell_async\n\n  File \"E:\\Apps\\Anaconda\\Lib\\site-packages\\IPython\\core\\interactiveshell.py\", line 3466, in run_ast_nodes\n\n  File \"E:\\Apps\\Anaconda\\Lib\\site-packages\\IPython\\core\\interactiveshell.py\", line 3526, in run_code\n\n  File \"C:\\Users\\Edgard\\AppData\\Local\\Temp\\ipykernel_31752\\181455356.py\", line 2, in <module>\n\n  File \"E:\\Apps\\Anaconda\\Lib\\site-packages\\keras\\src\\utils\\traceback_utils.py\", line 65, in error_handler\n\n  File \"E:\\Apps\\Anaconda\\Lib\\site-packages\\keras\\src\\engine\\training.py\", line 1807, in fit\n\n  File \"E:\\Apps\\Anaconda\\Lib\\site-packages\\keras\\src\\engine\\training.py\", line 1401, in train_function\n\n  File \"E:\\Apps\\Anaconda\\Lib\\site-packages\\keras\\src\\engine\\training.py\", line 1384, in step_function\n\n  File \"E:\\Apps\\Anaconda\\Lib\\site-packages\\keras\\src\\engine\\training.py\", line 1373, in run_step\n\n  File \"E:\\Apps\\Anaconda\\Lib\\site-packages\\keras\\src\\engine\\training.py\", line 1151, in train_step\n\n  File \"E:\\Apps\\Anaconda\\Lib\\site-packages\\keras\\src\\engine\\training.py\", line 1209, in compute_loss\n\n  File \"E:\\Apps\\Anaconda\\Lib\\site-packages\\keras\\src\\engine\\compile_utils.py\", line 277, in __call__\n\n  File \"E:\\Apps\\Anaconda\\Lib\\site-packages\\keras\\src\\losses.py\", line 143, in __call__\n\n  File \"E:\\Apps\\Anaconda\\Lib\\site-packages\\keras\\src\\losses.py\", line 270, in call\n\n  File \"E:\\Apps\\Anaconda\\Lib\\site-packages\\keras\\src\\losses.py\", line 2454, in sparse_categorical_crossentropy\n\n  File \"E:\\Apps\\Anaconda\\Lib\\site-packages\\keras\\src\\backend.py\", line 5775, in sparse_categorical_crossentropy\n\nlogits and labels must have the same first dimension, got logits shape [73728,6744] and labels shape [64]\n\t [[{{node sparse_categorical_crossentropy/SparseSoftmaxCrossEntropyWithLogits/SparseSoftmaxCrossEntropyWithLogits}}]] [Op:__inference_train_function_1034]",
     "output_type": "error",
     "traceback": [
      "\u001b[1;31m---------------------------------------------------------------------------\u001b[0m",
      "\u001b[1;31mInvalidArgumentError\u001b[0m                      Traceback (most recent call last)",
      "Cell \u001b[1;32mIn[7], line 2\u001b[0m\n\u001b[0;32m      1\u001b[0m \u001b[38;5;66;03m# Train the model\u001b[39;00m\n\u001b[1;32m----> 2\u001b[0m model\u001b[38;5;241m.\u001b[39mfit(X_train_vec\u001b[38;5;241m.\u001b[39mtoarray(), y_train_encoded, epochs\u001b[38;5;241m=\u001b[39m\u001b[38;5;241m5\u001b[39m, batch_size\u001b[38;5;241m=\u001b[39m\u001b[38;5;241m64\u001b[39m, validation_split\u001b[38;5;241m=\u001b[39m\u001b[38;5;241m0.1\u001b[39m)\n",
      "File \u001b[1;32mE:\\Apps\\Anaconda\\Lib\\site-packages\\keras\\src\\utils\\traceback_utils.py:70\u001b[0m, in \u001b[0;36mfilter_traceback.<locals>.error_handler\u001b[1;34m(*args, **kwargs)\u001b[0m\n\u001b[0;32m     67\u001b[0m     filtered_tb \u001b[38;5;241m=\u001b[39m _process_traceback_frames(e\u001b[38;5;241m.\u001b[39m__traceback__)\n\u001b[0;32m     68\u001b[0m     \u001b[38;5;66;03m# To get the full stack trace, call:\u001b[39;00m\n\u001b[0;32m     69\u001b[0m     \u001b[38;5;66;03m# `tf.debugging.disable_traceback_filtering()`\u001b[39;00m\n\u001b[1;32m---> 70\u001b[0m     \u001b[38;5;28;01mraise\u001b[39;00m e\u001b[38;5;241m.\u001b[39mwith_traceback(filtered_tb) \u001b[38;5;28;01mfrom\u001b[39;00m \u001b[38;5;28;01mNone\u001b[39;00m\n\u001b[0;32m     71\u001b[0m \u001b[38;5;28;01mfinally\u001b[39;00m:\n\u001b[0;32m     72\u001b[0m     \u001b[38;5;28;01mdel\u001b[39;00m filtered_tb\n",
      "File \u001b[1;32mE:\\Apps\\Anaconda\\Lib\\site-packages\\tensorflow\\python\\eager\\execute.py:53\u001b[0m, in \u001b[0;36mquick_execute\u001b[1;34m(op_name, num_outputs, inputs, attrs, ctx, name)\u001b[0m\n\u001b[0;32m     51\u001b[0m \u001b[38;5;28;01mtry\u001b[39;00m:\n\u001b[0;32m     52\u001b[0m   ctx\u001b[38;5;241m.\u001b[39mensure_initialized()\n\u001b[1;32m---> 53\u001b[0m   tensors \u001b[38;5;241m=\u001b[39m pywrap_tfe\u001b[38;5;241m.\u001b[39mTFE_Py_Execute(ctx\u001b[38;5;241m.\u001b[39m_handle, device_name, op_name,\n\u001b[0;32m     54\u001b[0m                                       inputs, attrs, num_outputs)\n\u001b[0;32m     55\u001b[0m \u001b[38;5;28;01mexcept\u001b[39;00m core\u001b[38;5;241m.\u001b[39m_NotOkStatusException \u001b[38;5;28;01mas\u001b[39;00m e:\n\u001b[0;32m     56\u001b[0m   \u001b[38;5;28;01mif\u001b[39;00m name \u001b[38;5;129;01mis\u001b[39;00m \u001b[38;5;129;01mnot\u001b[39;00m \u001b[38;5;28;01mNone\u001b[39;00m:\n",
      "\u001b[1;31mInvalidArgumentError\u001b[0m: Graph execution error:\n\nDetected at node sparse_categorical_crossentropy/SparseSoftmaxCrossEntropyWithLogits/SparseSoftmaxCrossEntropyWithLogits defined at (most recent call last):\n  File \"<frozen runpy>\", line 198, in _run_module_as_main\n\n  File \"<frozen runpy>\", line 88, in _run_code\n\n  File \"E:\\Apps\\Anaconda\\Lib\\site-packages\\ipykernel_launcher.py\", line 17, in <module>\n\n  File \"E:\\Apps\\Anaconda\\Lib\\site-packages\\traitlets\\config\\application.py\", line 992, in launch_instance\n\n  File \"E:\\Apps\\Anaconda\\Lib\\site-packages\\ipykernel\\kernelapp.py\", line 736, in start\n\n  File \"E:\\Apps\\Anaconda\\Lib\\site-packages\\tornado\\platform\\asyncio.py\", line 195, in start\n\n  File \"E:\\Apps\\Anaconda\\Lib\\asyncio\\base_events.py\", line 607, in run_forever\n\n  File \"E:\\Apps\\Anaconda\\Lib\\asyncio\\base_events.py\", line 1922, in _run_once\n\n  File \"E:\\Apps\\Anaconda\\Lib\\asyncio\\events.py\", line 80, in _run\n\n  File \"E:\\Apps\\Anaconda\\Lib\\site-packages\\ipykernel\\kernelbase.py\", line 516, in dispatch_queue\n\n  File \"E:\\Apps\\Anaconda\\Lib\\site-packages\\ipykernel\\kernelbase.py\", line 505, in process_one\n\n  File \"E:\\Apps\\Anaconda\\Lib\\site-packages\\ipykernel\\kernelbase.py\", line 412, in dispatch_shell\n\n  File \"E:\\Apps\\Anaconda\\Lib\\site-packages\\ipykernel\\kernelbase.py\", line 740, in execute_request\n\n  File \"E:\\Apps\\Anaconda\\Lib\\site-packages\\ipykernel\\ipkernel.py\", line 422, in do_execute\n\n  File \"E:\\Apps\\Anaconda\\Lib\\site-packages\\ipykernel\\zmqshell.py\", line 546, in run_cell\n\n  File \"E:\\Apps\\Anaconda\\Lib\\site-packages\\IPython\\core\\interactiveshell.py\", line 3024, in run_cell\n\n  File \"E:\\Apps\\Anaconda\\Lib\\site-packages\\IPython\\core\\interactiveshell.py\", line 3079, in _run_cell\n\n  File \"E:\\Apps\\Anaconda\\Lib\\site-packages\\IPython\\core\\async_helpers.py\", line 129, in _pseudo_sync_runner\n\n  File \"E:\\Apps\\Anaconda\\Lib\\site-packages\\IPython\\core\\interactiveshell.py\", line 3284, in run_cell_async\n\n  File \"E:\\Apps\\Anaconda\\Lib\\site-packages\\IPython\\core\\interactiveshell.py\", line 3466, in run_ast_nodes\n\n  File \"E:\\Apps\\Anaconda\\Lib\\site-packages\\IPython\\core\\interactiveshell.py\", line 3526, in run_code\n\n  File \"C:\\Users\\Edgard\\AppData\\Local\\Temp\\ipykernel_31752\\181455356.py\", line 2, in <module>\n\n  File \"E:\\Apps\\Anaconda\\Lib\\site-packages\\keras\\src\\utils\\traceback_utils.py\", line 65, in error_handler\n\n  File \"E:\\Apps\\Anaconda\\Lib\\site-packages\\keras\\src\\engine\\training.py\", line 1807, in fit\n\n  File \"E:\\Apps\\Anaconda\\Lib\\site-packages\\keras\\src\\engine\\training.py\", line 1401, in train_function\n\n  File \"E:\\Apps\\Anaconda\\Lib\\site-packages\\keras\\src\\engine\\training.py\", line 1384, in step_function\n\n  File \"E:\\Apps\\Anaconda\\Lib\\site-packages\\keras\\src\\engine\\training.py\", line 1373, in run_step\n\n  File \"E:\\Apps\\Anaconda\\Lib\\site-packages\\keras\\src\\engine\\training.py\", line 1151, in train_step\n\n  File \"E:\\Apps\\Anaconda\\Lib\\site-packages\\keras\\src\\engine\\training.py\", line 1209, in compute_loss\n\n  File \"E:\\Apps\\Anaconda\\Lib\\site-packages\\keras\\src\\engine\\compile_utils.py\", line 277, in __call__\n\n  File \"E:\\Apps\\Anaconda\\Lib\\site-packages\\keras\\src\\losses.py\", line 143, in __call__\n\n  File \"E:\\Apps\\Anaconda\\Lib\\site-packages\\keras\\src\\losses.py\", line 270, in call\n\n  File \"E:\\Apps\\Anaconda\\Lib\\site-packages\\keras\\src\\losses.py\", line 2454, in sparse_categorical_crossentropy\n\n  File \"E:\\Apps\\Anaconda\\Lib\\site-packages\\keras\\src\\backend.py\", line 5775, in sparse_categorical_crossentropy\n\nlogits and labels must have the same first dimension, got logits shape [73728,6744] and labels shape [64]\n\t [[{{node sparse_categorical_crossentropy/SparseSoftmaxCrossEntropyWithLogits/SparseSoftmaxCrossEntropyWithLogits}}]] [Op:__inference_train_function_1034]"
     ]
    }
   ],
   "source": [
    "# Train the model\n",
    "model.fit(X_train_vec.toarray(), y_train_encoded, epochs=5, batch_size=64, validation_split=0.1)"
   ]
  },
  {
   "cell_type": "code",
   "execution_count": 8,
   "id": "8e1da42c",
   "metadata": {},
   "outputs": [],
   "source": [
    "# Evaluate the model on the test set\n",
    "y_test_encoded = label_encoder.fit_transform(y_test)"
   ]
  },
  {
   "cell_type": "code",
   "execution_count": 9,
   "id": "fbee2ae1",
   "metadata": {},
   "outputs": [
    {
     "ename": "ValueError",
     "evalue": "Data cardinality is ambiguous:\n  x sizes: 10\n  y sizes: 1349\nMake sure all arrays contain the same number of samples.",
     "output_type": "error",
     "traceback": [
      "\u001b[1;31m---------------------------------------------------------------------------\u001b[0m",
      "\u001b[1;31mValueError\u001b[0m                                Traceback (most recent call last)",
      "Cell \u001b[1;32mIn[9], line 1\u001b[0m\n\u001b[1;32m----> 1\u001b[0m loss, accuracy \u001b[38;5;241m=\u001b[39m model\u001b[38;5;241m.\u001b[39mevaluate(X_test_vec\u001b[38;5;241m.\u001b[39mtoarray(), y_test_encoded)\n\u001b[0;32m      3\u001b[0m \u001b[38;5;28mprint\u001b[39m(\u001b[38;5;124mf\u001b[39m\u001b[38;5;124m'\u001b[39m\u001b[38;5;124mTest Loss: \u001b[39m\u001b[38;5;132;01m{\u001b[39;00mloss\u001b[38;5;132;01m:\u001b[39;00m\u001b[38;5;124m.4f\u001b[39m\u001b[38;5;132;01m}\u001b[39;00m\u001b[38;5;124m, Test Accuracy: \u001b[39m\u001b[38;5;132;01m{\u001b[39;00maccuracy\u001b[38;5;132;01m:\u001b[39;00m\u001b[38;5;124m.4f\u001b[39m\u001b[38;5;132;01m}\u001b[39;00m\u001b[38;5;124m'\u001b[39m)\n",
      "File \u001b[1;32mE:\\Apps\\Anaconda\\Lib\\site-packages\\keras\\src\\utils\\traceback_utils.py:70\u001b[0m, in \u001b[0;36mfilter_traceback.<locals>.error_handler\u001b[1;34m(*args, **kwargs)\u001b[0m\n\u001b[0;32m     67\u001b[0m     filtered_tb \u001b[38;5;241m=\u001b[39m _process_traceback_frames(e\u001b[38;5;241m.\u001b[39m__traceback__)\n\u001b[0;32m     68\u001b[0m     \u001b[38;5;66;03m# To get the full stack trace, call:\u001b[39;00m\n\u001b[0;32m     69\u001b[0m     \u001b[38;5;66;03m# `tf.debugging.disable_traceback_filtering()`\u001b[39;00m\n\u001b[1;32m---> 70\u001b[0m     \u001b[38;5;28;01mraise\u001b[39;00m e\u001b[38;5;241m.\u001b[39mwith_traceback(filtered_tb) \u001b[38;5;28;01mfrom\u001b[39;00m \u001b[38;5;28;01mNone\u001b[39;00m\n\u001b[0;32m     71\u001b[0m \u001b[38;5;28;01mfinally\u001b[39;00m:\n\u001b[0;32m     72\u001b[0m     \u001b[38;5;28;01mdel\u001b[39;00m filtered_tb\n",
      "File \u001b[1;32mE:\\Apps\\Anaconda\\Lib\\site-packages\\keras\\src\\engine\\data_adapter.py:1960\u001b[0m, in \u001b[0;36m_check_data_cardinality\u001b[1;34m(data)\u001b[0m\n\u001b[0;32m   1953\u001b[0m     msg \u001b[38;5;241m+\u001b[39m\u001b[38;5;241m=\u001b[39m \u001b[38;5;124m\"\u001b[39m\u001b[38;5;124m  \u001b[39m\u001b[38;5;132;01m{}\u001b[39;00m\u001b[38;5;124m sizes: \u001b[39m\u001b[38;5;132;01m{}\u001b[39;00m\u001b[38;5;130;01m\\n\u001b[39;00m\u001b[38;5;124m\"\u001b[39m\u001b[38;5;241m.\u001b[39mformat(\n\u001b[0;32m   1954\u001b[0m         label,\n\u001b[0;32m   1955\u001b[0m         \u001b[38;5;124m\"\u001b[39m\u001b[38;5;124m, \u001b[39m\u001b[38;5;124m\"\u001b[39m\u001b[38;5;241m.\u001b[39mjoin(\n\u001b[0;32m   1956\u001b[0m             \u001b[38;5;28mstr\u001b[39m(i\u001b[38;5;241m.\u001b[39mshape[\u001b[38;5;241m0\u001b[39m]) \u001b[38;5;28;01mfor\u001b[39;00m i \u001b[38;5;129;01min\u001b[39;00m tf\u001b[38;5;241m.\u001b[39mnest\u001b[38;5;241m.\u001b[39mflatten(single_data)\n\u001b[0;32m   1957\u001b[0m         ),\n\u001b[0;32m   1958\u001b[0m     )\n\u001b[0;32m   1959\u001b[0m msg \u001b[38;5;241m+\u001b[39m\u001b[38;5;241m=\u001b[39m \u001b[38;5;124m\"\u001b[39m\u001b[38;5;124mMake sure all arrays contain the same number of samples.\u001b[39m\u001b[38;5;124m\"\u001b[39m\n\u001b[1;32m-> 1960\u001b[0m \u001b[38;5;28;01mraise\u001b[39;00m \u001b[38;5;167;01mValueError\u001b[39;00m(msg)\n",
      "\u001b[1;31mValueError\u001b[0m: Data cardinality is ambiguous:\n  x sizes: 10\n  y sizes: 1349\nMake sure all arrays contain the same number of samples."
     ]
    }
   ],
   "source": [
    "loss, accuracy = model.evaluate(X_test_vec.toarray(), y_test_encoded)\n",
    "\n",
    "print(f'Test Loss: {loss:.4f}, Test Accuracy: {accuracy:.4f}')"
   ]
  },
  {
   "cell_type": "code",
   "execution_count": null,
   "id": "2257f832",
   "metadata": {},
   "outputs": [],
   "source": []
  }
 ],
 "metadata": {
  "kernelspec": {
   "display_name": "Python 3 (ipykernel)",
   "language": "python",
   "name": "python3"
  },
  "language_info": {
   "codemirror_mode": {
    "name": "ipython",
    "version": 3
   },
   "file_extension": ".py",
   "mimetype": "text/x-python",
   "name": "python",
   "nbconvert_exporter": "python",
   "pygments_lexer": "ipython3",
   "version": "3.11.5"
  }
 },
 "nbformat": 4,
 "nbformat_minor": 5
}
